Workbook

Sheet Instructivo
A1: Catálogo de Tenants — Vigma Consultores
A2: Propósito | B2: Centralizar la información de cada cliente (tenant) sin duplicar datos. Cada cliente tiene un único ClienteID que enlaza todas las hojas.
A3: Hojas | B3: 1) Clientes — datos generales 2) AccesosRemotos — AnyDesk/RustDesk por equipo 3) APIs_Timbrado — API Keys del Vigma Timbrado Gateway 4) APIs_FacturaLO — credenciales por cliente + cuenta maestra 5) UsuariosSistema — usuarios y contraseñas (ARC) 6) Infraestructura — VPS, RustDesk Server y otros datos técnicos 7) Vista_Resumen — consulta consolidada por ClienteID
A4: Reglas | B4: • Nunca repitas el nombre del cliente: usa el ClienteID. • Marca Estatus con la lista desplegable. • 'UltimaActualizacion' sirve de auditoría. • Protege el archivo con contraseña al cerrar (Archivo → Información → Proteger libro).
A5: Migración | B5: Datos migrados desde tu Tenants.xlsx original el 2026-05-03. Algunos campos (RFC, CP) podrían faltar; revísalos en la hoja Clientes.
A6: Tip | B6: Usa Ctrl+Shift+L para activar/desactivar filtros. Vista_Resumen tiene una lista desplegable arriba para cambiar de cliente.

Sheet Clientes
A1: Catálogo de Clientes
A2: ClienteID | B2: NombreCorto | C2: RazonSocial | D2: RFC | E2: Contacto | F2: Telefono | G2: Correo | H2: Direccion | I2: CP | J2: Estado | K2: Estatus | L2: UltimaActualizacion | M2: Notas
A3: T001 | B3: ACAXOCHITLAN | C3: MUNICIPIO DE ACAXOCHILTAN | D3: MAC8501016I4 | E3: DIRECTOR DEL AGUA | F3: 776 752 0090 | G3: acaxochitlan246@gmail.com | H3: Palacio Municipal s/n, Col. Centro, Acaxochitlan | J3: Hidalgo | K3: Activo | L3: 2026-05-03
A4: T002 | B4: ACTOPAN AGUA | C4: Comisión de Agua y alcantarillado de Actopán, Hidalgo | D4: CAA930101333 | E4: Gris CAASA | F4: 7721016818 | G4: comaguactopan@yahoo.com.mx | J4: Hidalgo | K4: Activo | L4: 2026-05-03
A5: T003 | B5: ACTOPAN PRESIDENCIA | C5: MUNICIPIO DE ACTOPAN | D5: MAC850101992 | E5: Contralora | G5: gabriela.garcia@vigmaconsulttores.com | I5: 42500 | J5: Hidalgo | K5: Activo | L5: 2026-05-03
A6: T004 | B6: AJACUBA | C6: COMISION DE AGUA Y SANEAMIENTO DEL MUNICIPIO DE AJACUBA HGO | D6: CAS141230736 | E6: CAYSA | F6: 773379886 | G6: caysa_ajacuba@yahoo.com.mx | J6: Hidalgo | K6: Activo | L6: 2026-05-03
A7: T005 | B7: ARC | C7: INDUSTRIAS ARC | D7: IAR9009251R9 | E7: Adellano | F7: 55 2724 7260 | G7: adellano@industriasarc.com.mx | H7: Cerrada Alfredo del Mazo No. 5, El Pedregal de Atizapán, Atizapán de Zaragoza | I7: 52948 | J7: Edo. México | K7: Activo | L7: 2026-05-03 | M7: Accesos por usuario en hoja AccesosArc
A8: T006 | B8: ARENAL | C8: COMISION DE AGUA POTABLE, ALCANTARILLADO Y SANEAMIENTO DEL MUNICIPIO DE EL ARENAL, HIDALGO, SISTEMA BOCJA - CHIMILPA | D8: CAP230608N2A | E8: Agua Arenal | G8: sistemaoperadorbocjachimilpa@gmail.com | H8: Antigua Vía del Ferrocarril s/n, El Bocja | I8: 42683 | J8: Hidalgo | K8: Activo | L8: 2026-05-03
A9: T007 | B9: CLASS LABELS | C9: CLASS LABELS S. DE R.L. DE C.V. | D9: CLA1504201Z8 | E9: Class Labels | F9: 5526204200 | G9: distribuidores@class-labels.com | H9: Independencia, Tultitlán de Mariano Escobedo | I9: 54915 | J9: Edo. México | K9: Activo | L9: 2026-05-03
A10: T008 | B10: CUAUTEPEC AGUA | C10: COMISION DE AGUA POTABLE, ALCANTARILLADO Y SANEAMIENTO DE CUAUTEPEC DE HINOJOSA HIDALGO | D10: CAP020708TX0 | E10: Yocelin Olivares | F10: 7757703600 | G10: aguapotbalecuautepec16@gmail.com | H10: Corregidora Sur 103, Plaza El Sol. Col. Centro, Cuautepec de Hinojosa | I10: 43740 | J10: Hidalgo | K10: Activo | L10: 2026-05-03
A11: T009 | B11: CUAUTEPEC ASERRADERO | C11: ORGANISMO OPERADOR DE AGUA POTABLE DEL ASERRADERO | D11: OOA211201TP6 | E11: Lic. Rubí Álvarez | G11: aguapro61@gmail.com | J11: Hidalgo | K11: Activo | L11: 2026-05-03
A12: T010 | B12: CUAUTEPEC PRESIDENCIA | C12: MUNICIPIO DE CUAUTEPEC DE HINOJOSA | D12: MCH850101BW8 | E12: Juan Carlos Ortiz Galindo | F12: 7540125 | G12: elopinga_60@hotmail.com | I12: 43740 | J12: Hidalgo | K12: Activo | L12: 2026-05-03 | M12: Predial / Presidencia
A13: T011 | B13: GARIN ETIQUETAS | C13: GARIN ETIQUETAS | D13: GET130827SN7 | E13: Alejandro de Paz | F13: 5566105972 | G13: alejandro@garinetiquetas.com | H13: Tezozomoc No. 9, Recursos Hidráulicos, Tultitlán de Mariano Escobedo | I13: 54913 | J13: Edo. México | K13: Activo | L13: 2026-05-03
A14: T012 | B14: HSD RFID | C14: HSD RFID CONVERTING | D14: HRC240521NC9 | E14: María Castro | F14: 3318114545 | G14: mariacastro.paxetiquetas@gmail.com | H14: Mz 2 Lt 35, 5 de Septiembre, Ecatepec de Morelos | I14: 55330 | J14: Edo. México | K14: Activo | L14: 2026-05-03
A15: T013 | B15: HUASCA | C15: COMISION DE AGUA DEL MUNICIPIO DE HUASCA DE OCAMPO HIDALGO | D15: CAM0602147WA | E15: Jazmín Teresa Ramírez Cortés | F15: 7717920101 | G15: coamh@hotmail.com | H15: Conocido s/n, Col. Centro, Huasca de Ocampo | I15: 43500 | J15: Hidalgo | K15: Activo | L15: 2026-05-03
A16: T014 | B16: HUEJUTLA | C16: COMISION DE AGUA POTABLE, ALCANTARILLADO Y SANEAMIENTO DE HUEJUTLA DE REYES, HGO | D16: CAA0207082R3 | E16: Zaida | F16: 01(789) 896-56-21 | G16: CAPASHH@hotmail.com | H16: Nicandro Castillo No. 25 Col. Centro, Huejutla de Reyes | I16: 43000 | J16: Hidalgo | K16: Activo | L16: 2026-05-03
A17: T015 | B17: MIXQUIAHUALA | C17: COMISION DE AGUA POTABLE Y ALCANTARILLADO DEL MUNICIPIO DE MIXQUIAHUALA DE JUAREZ HIDALGO | D17: CAP040210K23 | E17: CP Roque | F17: 7387350574 | G17: caamm_0402@hotmail.com | J17: Hidalgo | K17: Activo | L17: 2026-05-03
A18: T016 | B18: MULEGE (BC) | C18: ORGANISMO OPERADOR MUNICIPAL DEL SISTEMA DE AGUA POTABLE, ALCANTARILLADO Y SANEAMIENTO DE MULEGE | D18: OOM120125722 | E18: Brenda | F18: 7751269140 | G18: gabgv@msn.com | H18: Mulegé, Baja California Sur | J18: Baja California Sur | K18: Activo | L18: 2026-05-03 | M18: Cuenta varias localidades: Sta. Rosalía, Bahía Tortuga, Vizcaíno, Asunción, Abreojos, Guerrero Negro, San Ignacio, La Bocana
A19: T017 | B19: PROGRESO | C19: COMISION DE AGUA POTABLE, ALCANTARILLADO Y SANEAMIENTO DEL MUNICIPIO DE PROGRESO DE ALVARO OBREGON, HIDALGO | D19: CAA981221KEA | E19: Carmen Escamilla | F19: 7387250950 | G19: caampao_new_22@hotmail.com | J19: Hidalgo | K19: Activo | L19: 2026-05-03
A20: T018 | B20: TECOZAUTLA | C20: COMISION DE AGUA POTABLE,ALCANTARILLADO Y SANEAMIENTO DEL MUNICIPIO DE TECOZAUTLA | D20: CAP090310T24 | E20: Lic. Carolina | F20: 7751269140 | G20: gabriela.garcia.velazco@gmail.com | J20: Hidalgo | K20: Activo | L20: 2026-05-03
A21: T019 | B21: TEZONTEPEC | C21: COMISION DE AGUA Y ALCANTARILLADO DE TEZONTEPEC DE ALDAMA, HIDALGO | D21: CAA020223SN5 | E21: CAYATAH | G21: cayatah_2012@yahoo.com | J21: Hidalgo | K21: Activo | L21: 2026-05-03
A22: T020 | B22: VIGMA CONSULTORES | C22: VIGMA CONSULTORES SAS DE CV | D22: VCO1707276L0 | E22: Israel Villar Medina | F22: 7757546170 | G22: vigmac@prodigy.net.mx | H22: Pedro García Rangel 184, Col. Lázaro Cárdenas, Santiago Tulantepec | I22: 43760 | J22: Hidalgo | K22: Activo | L22: 2026-05-03 | M22: Cuenta propia
A23: T021 | B23: ZURICH ETIQUETAS | C23: ZURICH VILLAR GARCIA | D23: VIGZ980520ME5 | E23: Zurich Villar García | F23: 7751522351 | G23: zurich.villar@etiquetasdigitales.com | H23: Pedro García Rangel 213, Col. Lázaro Cárdenas, Santiago Tulantepec | I23: 43760 | J23: Hidalgo | K23: Activo | L23: 2026-05-03
A24: T022 | B24: ABAK | C24: ABAK (cliente) | K24: Activo | L24: 2026-05-03 | M24: Servidor en Tecnoweb (server164.tecnoweb.net)
A25: T023 | B25: SINDICATO CUAUTEPEC | C25: SINDICATO ÚNICO DE TRABAJADORES CUAUTEPEC | J25: Hidalgo | K25: Activo | L25: 2026-05-03 | M25: Plesk en 65.99.205.97

Sheet AccesosRemotos
A1: Accesos Remotos por Cliente
A2: ClienteID | B2: Cliente | C2: Tipo | D2: Area | E2: Equipo / Alias | F2: ID | G2: Password | H2: Notas | I2: UltimaActualizacion
A3: T004 | B3: =IFERROR(IF(A3="","",VLOOKUP(A3,Clientes!$A$3:$B$202,2,FALSE())),"") -> AJACUBA | C3: AnyDesk | E3: SERVER | F3: 1 174 989 621 | H3: MySQL: Gabriela2018 | I3: 2026-05-03
A4: T004 | B4: =IFERROR(IF(A4="","",VLOOKUP(A4,Clientes!$A$3:$B$202,2,FALSE())),"") -> AJACUBA | C4: RustDesk | E4: SERVER | F4: 22 464 940 | H4: MySQL: Gabriela2018 | I4: 2026-05-03
A5: T004 | B5: =IFERROR(IF(A5="","",VLOOKUP(A5,Clientes!$A$3:$B$202,2,FALSE())),"") -> AJACUBA | C5: AnyDesk | D5: CAJAS | E5: SERVIDOR COMUNIDADES | F5: 1835791957 | I5: 2026-05-03
A6: T004 | B6: =IFERROR(IF(A6="","",VLOOKUP(A6,Clientes!$A$3:$B$202,2,FALSE())),"") -> AJACUBA | C6: RustDesk | D6: CAJAS | E6: SERVIDOR COMUNIDADES | F6: 54 631 371 | I6: 2026-05-03
A7: T004 | B7: =IFERROR(IF(A7="","",VLOOKUP(A7,Clientes!$A$3:$B$202,2,FALSE())),"") -> AJACUBA | C7: AnyDesk | E7: CAJA FIJA (TECOMATLAN) | F7: 1 616 631 904 | I7: 2026-05-03
A8: T004 | B8: =IFERROR(IF(A8="","",VLOOKUP(A8,Clientes!$A$3:$B$202,2,FALSE())),"") -> AJACUBA | C8: RustDesk | E8: CAJA FIJA (TECOMATLAN) | F8: 22 455 870 | I8: 2026-05-03
A9: T004 | B9: =IFERROR(IF(A9="","",VLOOKUP(A9,Clientes!$A$3:$B$202,2,FALSE())),"") -> AJACUBA | C9: AnyDesk | E9: CAJA FIJA (SANTIAGO) | F9: 1175112487 | I9: 2026-05-03
A10: T004 | B10: =IFERROR(IF(A10="","",VLOOKUP(A10,Clientes!$A$3:$B$202,2,FALSE())),"") -> AJACUBA | C10: RustDesk | E10: CAJA FIJA (SANTIAGO) | F10: 22 471 019 | I10: 2026-05-03
A11: T004 | B11: =IFERROR(IF(A11="","",VLOOKUP(A11,Clientes!$A$3:$B$202,2,FALSE())),"") -> AJACUBA | C11: AnyDesk | D11: Comercial | E11: JOSELINE | F11: 1 805 331 651 | I11: 2026-05-03
A12: T004 | B12: =IFERROR(IF(A12="","",VLOOKUP(A12,Clientes!$A$3:$B$202,2,FALSE())),"") -> AJACUBA | C12: RustDesk | D12: Comercial | E12: JOSELINE | F12: 252 153 309 | I12: 2026-05-03
A13: T004 | B13: =IFERROR(IF(A13="","",VLOOKUP(A13,Clientes!$A$3:$B$202,2,FALSE())),"") -> AJACUBA | C13: AnyDesk | E13: AREA COMERCIAL(NELLY) | F13: 1703322057 | I13: 2026-05-03
A14: T004 | B14: =IFERROR(IF(A14="","",VLOOKUP(A14,Clientes!$A$3:$B$202,2,FALSE())),"") -> AJACUBA | C14: RustDesk | E14: AREA COMERCIAL(NELLY) | F14: 251 783 645 | I14: 2026-05-03
A15: T004 | B15: =IFERROR(IF(A15="","",VLOOKUP(A15,Clientes!$A$3:$B$202,2,FALSE())),"") -> AJACUBA | C15: RustDesk | E15: DIRECTOR | F15: 36 246 498 | I15: 2026-05-03
A16: T004 | B16: =IFERROR(IF(A16="","",VLOOKUP(A16,Clientes!$A$3:$B$202,2,FALSE())),"") -> AJACUBA | C16: AnyDesk | E16: LAPTOP - CAJA MOVIL | F16: 1 835 791 957 | H16: MySQL: Gabriela@2018 | I16: 2026-05-03
A17: T004 | B17: =IFERROR(IF(A17="","",VLOOKUP(A17,Clientes!$A$3:$B$202,2,FALSE())),"") -> AJACUBA | C17: RustDesk | E17: LAPTOP - CAJA MOVIL | F17: 54 631 371 | H17: MySQL: Gabriela@2018 | I17: 2026-05-03
A18: T002 | B18: =IFERROR(IF(A18="","",VLOOKUP(A18,Clientes!$A$3:$B$202,2,FALSE())),"") -> ACTOPAN AGUA | C18: AnyDesk | E18: SERVER AGUA | F18: 376585207 | H18: NIP: 15062021 (Windows) | I18: 2026-05-03
A19: T002 | B19: =IFERROR(IF(A19="","",VLOOKUP(A19,Clientes!$A$3:$B$202,2,FALSE())),"") -> ACTOPAN AGUA | C19: RustDesk | E19: SERVER AGUA | F19: 81 643 988 | H19: NIP: 15062021 (Windows) | I19: 2026-05-03
A20: T002 | B20: =IFERROR(IF(A20="","",VLOOKUP(A20,Clientes!$A$3:$B$202,2,FALSE())),"") -> ACTOPAN AGUA | C20: AnyDesk | D20: COMERCIAL| | E20: COMERCIAL| | F20: 1319977587 | H20: MySQL: Gabriela@2018 | I20: 2026-05-03
A21: T002 | B21: =IFERROR(IF(A21="","",VLOOKUP(A21,Clientes!$A$3:$B$202,2,FALSE())),"") -> ACTOPAN AGUA | C21: RustDesk | D21: COMERCIAL| | E21: COMERCIAL| | F21: 505 137 172 | H21: MySQL: Gabriela@2018 | I21: 2026-05-03
A22: T002 | B22: =IFERROR(IF(A22="","",VLOOKUP(A22,Clientes!$A$3:$B$202,2,FALSE())),"") -> ACTOPAN AGUA | C22: AnyDesk | E22: SANDRA | F22: 1182857572 | H22: caduca cert. 11 nov- 2025 | SUSPENDIDA | I22: 2026-05-03
A23: T002 | B23: =IFERROR(IF(A23="","",VLOOKUP(A23,Clientes!$A$3:$B$202,2,FALSE())),"") -> ACTOPAN AGUA | C23: RustDesk | E23: SANDRA | F23: 514 480 131 | H23: caduca cert. 11 nov- 2025 | SUSPENDIDA | I23: 2026-05-03
A24: T002 | B24: =IFERROR(IF(A24="","",VLOOKUP(A24,Clientes!$A$3:$B$202,2,FALSE())),"") -> ACTOPAN AGUA | C24: AnyDesk | E24: SANDRA NUEVA COMPU | F24: 1 523 374 180 | I24: 2026-05-03
A25: T002 | B25: =IFERROR(IF(A25="","",VLOOKUP(A25,Clientes!$A$3:$B$202,2,FALSE())),"") -> ACTOPAN AGUA | C25: RustDesk | E25: SANDRA NUEVA COMPU | F25: 157 106 719 | I25: 2026-05-03
A26: T002 | B26: =IFERROR(IF(A26="","",VLOOKUP(A26,Clientes!$A$3:$B$202,2,FALSE())),"") -> ACTOPAN AGUA | C26: AnyDesk | E26: VALERIA | F26: 1170994117 | H26: actu | I26: 2026-05-03
A27: T002 | B27: =IFERROR(IF(A27="","",VLOOKUP(A27,Clientes!$A$3:$B$202,2,FALSE())),"") -> ACTOPAN AGUA | C27: RustDesk | E27: VALERIA | F27: 3 296 040 | H27: actu | I27: 2026-05-03
A28: T002 | B28: =IFERROR(IF(A28="","",VLOOKUP(A28,Clientes!$A$3:$B$202,2,FALSE())),"") -> ACTOPAN AGUA | C28: AnyDesk | E28: Aministrativo Eduardo | F28: 1 329 737 810 | I28: 2026-05-03
A29: T002 | B29: =IFERROR(IF(A29="","",VLOOKUP(A29,Clientes!$A$3:$B$202,2,FALSE())),"") -> ACTOPAN AGUA | C29: RustDesk | E29: Aministrativo Eduardo | F29: 62 582 087 | I29: 2026-05-03
A30: T002 | B30: =IFERROR(IF(A30="","",VLOOKUP(A30,Clientes!$A$3:$B$202,2,FALSE())),"") -> ACTOPAN AGUA | C30: AnyDesk | D30: COBRO | E30: CAJA 3 HARIF | F30: 613 682 799 | H30: SUSPENDIDA | I30: 2026-05-03
A31: T002 | B31: =IFERROR(IF(A31="","",VLOOKUP(A31,Clientes!$A$3:$B$202,2,FALSE())),"") -> ACTOPAN AGUA | C31: RustDesk | D31: COBRO | E31: CAJA 3 HARIF | F31: 320 099 641 | H31: SUSPENDIDA | I31: 2026-05-03
A32: T002 | B32: =IFERROR(IF(A32="","",VLOOKUP(A32,Clientes!$A$3:$B$202,2,FALSE())),"") -> ACTOPAN AGUA | C32: AnyDesk | E32: CAJA 3 JARE | F32: 1788547954 | I32: 2026-05-03
A33: T002 | B33: =IFERROR(IF(A33="","",VLOOKUP(A33,Clientes!$A$3:$B$202,2,FALSE())),"") -> ACTOPAN AGUA | C33: RustDesk | E33: CAJA 3 JARE | F33: 157 106 890 | I33: 2026-05-03
A34: T002 | B34: =IFERROR(IF(A34="","",VLOOKUP(A34,Clientes!$A$3:$B$202,2,FALSE())),"") -> ACTOPAN AGUA | C34: AnyDesk | E34: CAJA 2 HARIF | F34: 1 060 400 026 | I34: 2026-05-03
A35: T002 | B35: =IFERROR(IF(A35="","",VLOOKUP(A35,Clientes!$A$3:$B$202,2,FALSE())),"") -> ACTOPAN AGUA | C35: RustDesk | E35: CAJA 2 HARIF | F35: 3 296 079 | I35: 2026-05-03
A36: T002 | B36: =IFERROR(IF(A36="","",VLOOKUP(A36,Clientes!$A$3:$B$202,2,FALSE())),"") -> ACTOPAN AGUA | C36: AnyDesk | E36: CAJA 1- (NUEVA) | F36: 1927895025 | I36: 2026-05-03
A37: T002 | B37: =IFERROR(IF(A37="","",VLOOKUP(A37,Clientes!$A$3:$B$202,2,FALSE())),"") -> ACTOPAN AGUA | C37: RustDesk | E37: CAJA 1- (NUEVA) | F37: 157 103 707 | I37: 2026-05-03
A38: T002 | B38: =IFERROR(IF(A38="","",VLOOKUP(A38,Clientes!$A$3:$B$202,2,FALSE())),"") -> ACTOPAN AGUA | C38: Otro / Nota | H38: actua | I38: 2026-05-03
A39: T002 | B39: =IFERROR(IF(A39="","",VLOOKUP(A39,Clientes!$A$3:$B$202,2,FALSE())),"") -> ACTOPAN AGUA | C39: AnyDesk | E39: CAJA - Móvil | F39: 1771652910 | I39: 2026-05-03
A40: T002 | B40: =IFERROR(IF(A40="","",VLOOKUP(A40,Clientes!$A$3:$B$202,2,FALSE())),"") -> ACTOPAN AGUA | C40: RustDesk | E40: CAJA - Móvil | F40: 298 040 328 | I40: 2026-05-03
...

Sheet APIs_Timbrado
A1: API Keys de Timbrado (Vigma Timbrado Gateway)
A2: ClienteID | B2: Cliente | C2: Referencia | D2: PAC | E2: Ambiente | F2: API Key | G2: Notas | H2: UltimaActualizacion
A3: T020 | B3: =IFERROR(IF(A3="","",VLOOKUP(A3,Clientes!$A$3:$B$202,2,FALSE())),"") -> VIGMA CONSULTORES | C3: Demo | D3: Vigma Timbrado Gateway | E3: Producción | F3: tg_live_d3f23b1248d9f0005f482f2ab83a5fe4c793f2a12773494aed33f3de325dd681 | G3: Pruebas / Demo | H3: 2026-05-03
A4: T022 | B4: =IFERROR(IF(A4="","",VLOOKUP(A4,Clientes!$A$3:$B$202,2,FALSE())),"") -> ABAK | C4: abak | D4: Vigma Timbrado Gateway | E4: Producción | F4: tg_live_360087a2bc7a5c2e9035fc7f8958016bdc134fb2633f9154d53bd4fd65535664 | H4: 2026-05-03
A5: T020 | B5: =IFERROR(IF(A5="","",VLOOKUP(A5,Clientes!$A$3:$B$202,2,FALSE())),"") -> VIGMA CONSULTORES | C5: vigma | D5: Vigma Timbrado Gateway | E5: Producción | F5: tg_live_c51f853a34d9c03d7fce7ea18895a08593a0ce5524ab0c594f0e0a9d174e3063 | H5: 2026-05-03
A6: T021 | B6: =IFERROR(IF(A6="","",VLOOKUP(A6,Clientes!$A$3:$B$202,2,FALSE())),"") -> ZURICH ETIQUETAS | C6: zurich | D6: Vigma Timbrado Gateway | E6: Pruebas | F6: tg_test_2b42e00c576b2457544313a53f8336bd9fb8cb78b9e107b4f10c133e16c6f34c | H6: 2026-05-03
A7: T016 | B7: =IFERROR(IF(A7="","",VLOOKUP(A7,Clientes!$A$3:$B$202,2,FALSE())),"") -> MULEGE (BC) | C7: Mulege | D7: Vigma Timbrado Gateway | E7: Producción | F7: tg_live_6695a78a5549957789a16a711b721d77ab918a0a8be8d5b03ccd5b6eeb002b12 | H7: 2026-05-03
A8: T015 | B8: =IFERROR(IF(A8="","",VLOOKUP(A8,Clientes!$A$3:$B$202,2,FALSE())),"") -> MIXQUIAHUALA | C8: Mixquihuala | D8: Vigma Timbrado Gateway | E8: Producción | F8: tg_live_82ecb8e7802160ed8ca57d18beef8a850fcbc0df28282b17a7409cc30156647e | H8: 2026-05-03
A9: T009 | B9: =IFERROR(IF(A9="","",VLOOKUP(A9,Clientes!$A$3:$B$202,2,FALSE())),"") -> CUAUTEPEC ASERRADERO | C9: Aserradero | D9: Vigma Timbrado Gateway | E9: Producción | F9: tg_live_2fef060cc206e3047989a49bffb28fd1a263ac634fa5fc3379cac647d8e5376e | H9: 2026-05-03
A10: T014 | B10: =IFERROR(IF(A10="","",VLOOKUP(A10,Clientes!$A$3:$B$202,2,FALSE())),"") -> HUEJUTLA | C10: huejutla | D10: Vigma Timbrado Gateway | E10: Producción | F10: tg_live_8abfe33dcfd9552a7f3b78712d57053923e449ec6747bae8a85e158b41caf611 | H10: 2026-05-03
A11: T017 | B11: =IFERROR(IF(A11="","",VLOOKUP(A11,Clientes!$A$3:$B$202,2,FALSE())),"") -> PROGRESO | C11: progreso | D11: Vigma Timbrado Gateway | E11: Producción | F11: tg_live_b4fb412ae7b389ca9297edbc2369b5b727a6326c8f64f8ff33cdd2e421c464fa | H11: 2026-05-03
A12: T007 | B12: =IFERROR(IF(A12="","",VLOOKUP(A12,Clientes!$A$3:$B$202,2,FALSE())),"") -> CLASS LABELS | C12: class | D12: Vigma Timbrado Gateway | E12: Producción | F12: tg_live_1d066054347801ef6805a87d7f4fd15687de56a5d502f93d615294838447e3df | H12: 2026-05-03
A13: T002 | B13: =IFERROR(IF(A13="","",VLOOKUP(A13,Clientes!$A$3:$B$202,2,FALSE())),"") -> ACTOPAN AGUA | C13: Agua Actopan | D13: Vigma Timbrado Gateway | E13: Producción | F13: tg_live_c2b137be7c532c367edc09ad03390f9dc8753837e363e1d005917fbe28bd1373 | H13: 2026-05-03
A14: T019 | B14: =IFERROR(IF(A14="","",VLOOKUP(A14,Clientes!$A$3:$B$202,2,FALSE())),"") -> TEZONTEPEC | C14: Tezontepec | D14: Vigma Timbrado Gateway | E14: Producción | F14: tg_live_dfbc1f15d7f43c4c17fc0803e68da752c1c33d3540ce19cdeb547224655d5e88 | H14: 2026-05-03
A15: T004 | B15: =IFERROR(IF(A15="","",VLOOKUP(A15,Clientes!$A$3:$B$202,2,FALSE())),"") -> AJACUBA | C15: ajacuba | D15: Vigma Timbrado Gateway | E15: Producción | F15: tg_live_320e3b73048d8c240de5e407824b6ca72cb8acfb4b0c0fb6c73ee92f7058139e | H15: 2026-05-03
... A19: T013 | B19: =IFERROR(IF(A19="","",VLOOKUP(A19,Clientes!$A$3:$B$202,2,FALSE())),"") -> HUASCA | C19: Huasca | D19: Vigma Timbrado Gateway | E19: Producción | F19: tg_live_10b553e1166f34078dc2560c01f23ac8fd458cde8f7413bdfae45efa38b8c628 | H19: 2026-05-03
B20: =IFERROR(IF(A20="","",VLOOKUP(A20,Clientes!$A$3:$B$202,2,FALSE())),"")
B21: =IFERROR(IF(A21="","",VLOOKUP(A21,Clientes!$A$3:$B$202,2,FALSE())),"")
B22: =IFERROR(IF(A22="","",VLOOKUP(A22,Clientes!$A$3:$B$202,2,FALSE())),"")
B23: =IFERROR(IF(A23="","",VLOOKUP(A23,Clientes!$A$3:$B$202,2,FALSE())),"")
B24: =IFERROR(IF(A24="","",VLOOKUP(A24,Clientes!$A$3:$B$202,2,FALSE())),"")
B25: =IFERROR(IF(A25="","",VLOOKUP(A25,Clientes!$A$3:$B$202,2,FALSE())),"")
B26: =IFERROR(IF(A26="","",VLOOKUP(A26,Clientes!$A$3:$B$202,2,FALSE())),"")
B27: =IFERROR(IF(A27="","",VLOOKUP(A27,Clientes!$A$3:$B$202,2,FALSE())),"")
B28: =IFERROR(IF(A28="","",VLOOKUP(A28,Clientes!$A$3:$B$202,2,FALSE())),"")
B29: =IFERROR(IF(A29="","",VLOOKUP(A29,Clientes!$A$3:$B$202,2,FALSE())),"")
B30: =IFERROR(IF(A30="","",VLOOKUP(A30,Clientes!$A$3:$B$202,2,FALSE())),"")
B31: =IFERROR(IF(A31="","",VLOOKUP(A31,Clientes!$A$3:$B$202,2,FALSE())),"")
... B202: =IFERROR(IF(A202="","",VLOOKUP(A202,Clientes!$A$3:$B$202,2,FALSE())),"")

Sheet APIs_FacturaLO
A1: Credenciales Factura.LO
A3: CUENTA MAESTRA (Factura.LO)
A4: Cuenta | B4: VIGMA CONSULTORES
A5: Usuario | B5: admin34060
A6: Password | B6: Aa94054$
A7: API Key Maestra | B7: 765b14787451476dbb4ab6a9e3a10cb1
A8: Web Service SOAP | B8: https://app.facturaloplus.com/ws/servicio.do?wsdl
A9: Web Service REST | B9: https://app.facturaloplus.com/api/rest/servicio/
A10: CPanel | B10: https://panel.facturaloplus.com/usuarios/login
A12: API KEY POR CLIENTE
A13: ClienteID | B13: Cliente | C13: Razon Social | D13: RFC | E13: API Key | F13: Contacto | G13: Telefono | H13: Correo | I13: UltimaActualizacion
A14: T019 | B14: =IFERROR(IF(A14="","",VLOOKUP(A14,Clientes!$A$3:$B$202,2,FALSE())),"") -> TEZONTEPEC | C14: COMISION DE AGUA Y ALCANTARILLADO DE TEZONTEPEC DE ALDAMA, HIDALGO | D14: CAA020223SN5 | E14: 30fe4871251b4904a1daf115f148a706 | F14: CAYATAH | H14: cayatah_2012@yahoo.com | I14: 2026-05-03
A15: T014 | B15: =IFERROR(IF(A15="","",VLOOKUP(A15,Clientes!$A$3:$B$202,2,FALSE())),"") -> HUEJUTLA | C15: COMISION DE AGUA POTABLE, ALCANTARILLADO Y SANEAMIENTO DE HUEJUTLA DE REYES, HGO | D15: CAA0207082R3 | E15: ad1e4e421a0b4a3ba48e6c79e7b0f510 | F15: ZAIDA | G15: 01(789) 896-56-21 | H15: CAPASHH@hotmail.com | I15: 2026-05-03
A16: T002 | B16: =IFERROR(IF(A16="","",VLOOKUP(A16,Clientes!$A$3:$B$202,2,FALSE())),"") -> ACTOPAN AGUA | C16: Comisión de Agua y alcantarillado de Actopán, Hidalgo | D16: CAA930101333 | E16: 471b10b21c9d467283b605ee9ae07abb | F16: Gris CAASA | G16: 7721016818.0 | H16: comaguactopan@yahoo.com.mx | I16: 2026-05-03
A17: T017 | B17: =IFERROR(IF(A17="","",VLOOKUP(A17,Clientes!$A$3:$B$202,2,FALSE())),"") -> PROGRESO | C17: COMISION DE AGUA Y ALCANTARILLADO DEL MUNICIPIO DE PROGRESO DE ALVARO OBREGON, HIDALGO | D17: CAA981221KEA | E17: a6f4fd6e09794cbeb1937bf5fa5d13fe | F17: CARMEN ESCAMILLA | G17: 7387250950.0 | H17: caampao_new_22@hotmail.com | I17: 2026-05-03
A18: T013 | B18: =IFERROR(IF(A18="","",VLOOKUP(A18,Clientes!$A$3:$B$202,2,FALSE())),"") -> HUASCA | C18: COMISION DE AGUA DEL MUNICIPIO DE HUASCA DE OCAMPO HIDALGO | D18: CAM0602147WA | E18: 08808511cf754e4c8ac7144d517fc3eb | F18: JAZMIN TERESA RAMIREZ CORTES | G18: 7717920101.0 | H18: coamh@hotmail.com | I18: 2026-05-03
A19: T008 | B19: =IFERROR(IF(A19="","",VLOOKUP(A19,Clientes!$A$3:$B$202,2,FALSE())),"") -> CUAUTEPEC AGUA | C19: COMISION DE AGUA POTABLE, ALCANTARILLADO Y SANEAMIENTO DE CUAUTEPEC DE HINOJOSA HIDALGO | D19: CAP020708TX0 | E19: 26ce23f2f08443c9a031403b06b3544a | F19: Yocelin Olivares | G19: 7757703600.0 | H19: aguapotbalecuautepec16@gmail.com | I19: 2026-05-03
A20: T015 | B20: =IFERROR(IF(A20="","",VLOOKUP(A20,Clientes!$A$3:$B$202,2,FALSE())),"") -> MIXQUIAHUALA | C20: COMISION DE AGUA POTABLE Y ALCANTARILLADO DEL MUNICIPIO DE MIXQUIAHUALA DE JUAREZ HIDALGO | D20: CAP040210K23 | E20: 6652e2cce3054248b0f013d95e925d97 | F20: CP Roque | G20: 7387350574.0 | H20: caamm_0402@hotmail.com | I20: 2026-05-03
A21: T018 | B21: =IFERROR(IF(A21="","",VLOOKUP(A21,Clientes!$A$3:$B$202,2,FALSE())),"") -> TECOZAUTLA | C21: COMISION DE AGUA POTABLE,ALCANTARILLADO Y SANEAMIENTO DEL MUNICIPIO DE TECOZAUTLA | D21: CAP090310T24 | E21: 864e0fd34be74feca7628a7a08158f3c | F21: Lic. CAROLINA | G21: 7751269140.0 | H21: gabriela.garcia.velazco@gmail.com | I21: 2026-05-03
A22: T006 | B22: =IFERROR(IF(A22="","",VLOOKUP(A22,Clientes!$A$3:$B$202,2,FALSE())),"") -> ARENAL | C22: COMISION DE AGUA POTABLE, ALCANTARILLADO Y SANEAMIENTO DEL MUNICIPIO DE EL ARENAL, HIDALGO, SISTEMA BOCJA - CHIMILPA | D22: CAP230608N2A | E22: 7cd3c8ad17044ee9aeb6d6f95e2f5d6e | F22: AGUA ARENAL | H22: sistemaoperadorbocjachimilpa@gmail.com | I22: 2026-05-03
A23: T004 | B23: =IFERROR(IF(A23="","",VLOOKUP(A23,Clientes!$A$3:$B$202,2,FALSE())),"") -> AJACUBA | C23: COMISION DE AGUA Y SANEAMIENTO DEL MUNICIPIO DE AJACUBA HGO | D23: CAS141230736 | E23: 212d4200384e417ea586dd9713385146 | F23: CAYSA | G23: 773379886.0 | H23: caysa_ajacuba@yahoo.com.mx | I23: 2026-05-03
A24: T001 | B24: =IFERROR(IF(A24="","",VLOOKUP(A24,Clientes!$A$3:$B$202,2,FALSE())),"") -> ACAXOCHITLAN | C24: MUNICIPIO DE ACAXOCHILTAN | D24: MAC8501016I4 | E24: 7a5a02208efb4530acdef104b6873c23 | F24: DIRECTOR DEL AGUA | G24: 776 752 0090 | H24: acaxochitlan246@gmail.com | I24: 2026-05-03
A25: T003 | B25: =IFERROR(IF(A25="","",VLOOKUP(A25,Clientes!$A$3:$B$202,2,FALSE())),"") -> ACTOPAN PRESIDENCIA | C25: MUNICIPIO DE ACTOPAN | D25: MAC850101992 | E25: 1f890ebc319f4f4bb1bc7084918dae60 | F25: CONTRALORA | H25: gabriela.garcia@vigmaconsulttores.com | I25: 2026-05-03
A26: T010 | B26: =IFERROR(IF(A26="","",VLOOKUP(A26,Clientes!$A$3:$B$202,2,FALSE())),"") -> CUAUTEPEC PRESIDENCIA | C26: MUNICIPIO DE CUAUTEPEC DE HINOJOSA | D26: MCH850101BW8 | E26: b8996ac3cf234aa48f978d2f1c1f7971 | F26: JUAN CARLOS ORTIZ GALINDO | G26: 7540125.0 | H26: elopinga_60@hotmail.com | I26: 2026-05-03
A27: T009 | B27: =IFERROR(IF(A27="","",VLOOKUP(A27,Clientes!$A$3:$B$202,2,FALSE())),"") -> CUAUTEPEC ASERRADERO | C27: ORGANISMO OPERADOR DE AGUA POTABLE DEL ASERRADERO | D27: OOA211201TP6 | E27: 8d3fa7dc7805401384d986f8576e61e3 | F27: LIC RUBI ALVAREZ | H27: aguapro61@gmail.com | I27: 2026-05-03
A28: T016 | B28: =IFERROR(IF(A28="","",VLOOKUP(A28,Clientes!$A$3:$B$202,2,FALSE())),"") -> MULEGE (BC) | C28: ORGANISMO OPERADOR MUNICIPAL DEL SISTEMA DE AGUA POTABLE, ALCANTARILLADO Y SANEAMIENTO DE MULEGE | D28: OOM120125722 | E28: e135861bfef74a5bae5445ade128ae5e | F28: BRENDA | G28: 7751269140.0 | H28: gabgv@msn.com | I28: 2026-05-03
A29: T020 | B29: =IFERROR(IF(A29="","",VLOOKUP(A29,Clientes!$A$3:$B$202,2,FALSE())),"") -> VIGMA CONSULTORES | C29: VIGMA CONSULTORES SAS DE CV | D29: VCO1707276L0 | E29: 3a4b85b8b86c45adae6f31aedc3fd077 | F29: ISRAEL VILLAR MEDINA | G29: 7757546170.0 | H29: vigmac@prodigy.net.mx | I29: 2026-05-03
A30: T021 | B30: =IFERROR(IF(A30="","",VLOOKUP(A30,Clientes!$A$3:$B$202,2,FALSE())),"") -> ZURICH ETIQUETAS | C30: ZURICH VILLAR GARCIA | D30: VIGZ980520ME5 | E30: e5a00683a046477fae3e3c96253385bc | F30: ZURICH VILLAR GARCIA | G30: 7751522351.0 | H30: zurich.villar@etiquetasdigitales.com | I30: 2026-05-03
A31: T007 | B31: =IFERROR(IF(A31="","",VLOOKUP(A31,Clientes!$A$3:$B$202,2,FALSE())),"") -> CLASS LABELS | C31: CLASS LABELS S. DE R.L. DE C.V. | D31: CLA1504201Z8 | E31: 421e190578f448918b40c291d0cbc098 | F31: CLASS LABELS S. DE R.L. DE C.V. | G31: 55262042000.0 | H31: distribuidores@class-labels.com | I31: 2026-05-03
A32: T011 | B32: =IFERROR(IF(A32="","",VLOOKUP(A32,Clientes!$A$3:$B$202,2,FALSE())),"") -> GARIN ETIQUETAS | C32: GARIN ETIQUETAS | D32: GET130827SN7 | E32: 3245a05a9dad400590c3d0a873ccf237 | F32: ALEJANDRO DE PAZ | G32: 5566105972.0 | H32: alejandro@garinetiquetas.com | I32: 2026-05-03
A33: T012 | B33: =IFERROR(IF(A33="","",VLOOKUP(A33,Clientes!$A$3:$B$202,2,FALSE())),"") -> HSD RFID | C33: HSD RFID CONVERTING | D33: HRC240521NC9 | E33: de724ef419004c26bf364c3ca2302a80 | F33: HSD RFID CONVERTING | G33: 3318114545.0 | H33: mariacastro.paxetiquetas@gmail.com | I33: 2026-05-03
A34: T005 | B34: =IFERROR(IF(A34="","",VLOOKUP(A34,Clientes!$A$3:$B$202,2,FALSE())),"") -> ARC | C34: INDUSTRIAS ARC | D34: IAR9009251R9 | E34: 86299ad4d9a34f7382429ccfa69712d9 | F34: INDUSTRIAS ARC | G34: 55 2724 7260 | H34: adellano@industriasarc.com.mx | I34: 2026-05-03
B35: =IFERROR(IF(A35="","",VLOOKUP(A35,Clientes!$A$3:$B$202,2,FALSE())),"")
B36: =IFERROR(IF(A36="","",VLOOKUP(A36,Clientes!$A$3:$B$202,2,FALSE())),"")
B37: =IFERROR(IF(A37="","",VLOOKUP(A37,Clientes!$A$3:$B$202,2,FALSE())),"")
B38: =IFERROR(IF(A38="","",VLOOKUP(A38,Clientes!$A$3:$B$202,2,FALSE())),"")
B39: =IFERROR(IF(A39="","",VLOOKUP(A39,Clientes!$A$3:$B$202,2,FALSE())),"")
B40: =IFERROR(IF(A40="","",VLOOKUP(A40,Clientes!$A$3:$B$202,2,FALSE())),"")
B41: =IFERROR(IF(A41="","",VLOOKUP(A41,Clientes!$A$3:$B$202,2,FALSE())),"")
B42: =IFERROR(IF(A42="","",VLOOKUP(A42,Clientes!$A$3:$B$202,2,FALSE())),"")
...

Sheet UsuariosSistema
A1: Usuarios del Sistema (por cliente)
A2: ClienteID | B2: Cliente | C2: Usuario | D2: Password | E2: Area | F2: Correo | G2: NombreCompleto | H2: UltimaActualizacion
A3: T005 | B3: =IFERROR(IF(A3="","",VLOOKUP(A3,Clientes!$A$3:$B$202,2,FALSE())),"") -> ARC | C3: Patricia | D3: Escoto@2025 | E3: Ventas | F3: mp.escoto@industriasarc.com.mx | G3: PATRICIA ESCOTO | H3: 2026-05-03
A4: T005 | B4: =IFERROR(IF(A4="","",VLOOKUP(A4,Clientes!$A$3:$B$202,2,FALSE())),"") -> ARC | C4: Orly | D4: LoraV@2025 | E4: Ventas | F4: o.garduno@insdustriasarc.com.mx | G4: ORLY GARDUÑO LORA | H4: 2026-05-03
A5: T005 | B5: =IFERROR(IF(A5="","",VLOOKUP(A5,Clientes!$A$3:$B$202,2,FALSE())),"") -> ARC | C5: Rafael | D5: RubIo@2025 | E5: Ventas | F5: r.rubio@industriasarc.com.mx | G5: RAFAEL RUBIO | H5: 2026-05-03
A6: T005 | B6: =IFERROR(IF(A6="","",VLOOKUP(A6,Clientes!$A$3:$B$202,2,FALSE())),"") -> ARC | C6: Elizabeth | D6: eqe3@2025 | E6: Ventas | F6: elizabethrqe3@gamil.com | G6: ELIZABETH RUEDA QUIJANO | H6: 2026-05-03
A7: T005 | B7: =IFERROR(IF(A7="","",VLOOKUP(A7,Clientes!$A$3:$B$202,2,FALSE())),"") -> ARC | C7: Daniel | D7: Daniel@2025% | E7: Almacenista | F7: dany,salazarfrias@outlook.com | G7: DANIEL ZALASAR FRIAS | H7: 2026-05-03
A8: T005 | B8: =IFERROR(IF(A8="","",VLOOKUP(A8,Clientes!$A$3:$B$202,2,FALSE())),"") -> ARC | C8: Jose Alberto | D8: Srey@2025 | E8: Almacenista | F8: Contraseña de sistema y de almacenista | G8: JOSE ALBERTO SANCHES REYES | H8: 2026-05-03
A9: T005 | B9: =IFERROR(IF(A9="","",VLOOKUP(A9,Clientes!$A$3:$B$202,2,FALSE())),"") -> ARC | C9: German | D9: German@2025 | E9: Planeacion | F9: g.brizeno@industriasarc.com.mx | G9: GERMAN ALEJANDRO BRIZEÑO GARCIA | H9: 2026-05-03
A10: T005 | B10: =IFERROR(IF(A10="","",VLOOKUP(A10,Clientes!$A$3:$B$202,2,FALSE())),"") -> ARC | C10: Emmitt | D10: Emmitt@2025 | E10: Planeacion | F10: emmitt1096@gmail.com | G10: EMMITT DANCE CUREÑO MORALES | H10: 2026-05-03
A11: T005 | B11: =IFERROR(IF(A11="","",VLOOKUP(A11,Clientes!$A$3:$B$202,2,FALSE())),"") -> ARC | C11: JuanC | D11: JuanC@2025% | E11: Produccion | F11: jccr1369@hotmail.com | G11: JUAN CARLOS CRUZ | H11: 2026-05-03
B12: =IFERROR(IF(A12="","",VLOOKUP(A12,Clientes!$A$3:$B$202,2,FALSE())),"")
B13: =IFERROR(IF(A13="","",VLOOKUP(A13,Clientes!$A$3:$B$202,2,FALSE())),"")
B14: =IFERROR(IF(A14="","",VLOOKUP(A14,Clientes!$A$3:$B$202,2,FALSE())),"")
B15: =IFERROR(IF(A15="","",VLOOKUP(A15,Clientes!$A$3:$B$202,2,FALSE())),"")
B16: =IFERROR(IF(A16="","",VLOOKUP(A16,Clientes!$A$3:$B$202,2,FALSE())),"")
B17: =IFERROR(IF(A17="","",VLOOKUP(A17,Clientes!$A$3:$B$202,2,FALSE())),"")
B18: =IFERROR(IF(A18="","",VLOOKUP(A18,Clientes!$A$3:$B$202,2,FALSE())),"")
B19: =IFERROR(IF(A19="","",VLOOKUP(A19,Clientes!$A$3:$B$202,2,FALSE())),"")
B20: =IFERROR(IF(A20="","",VLOOKUP(A20,Clientes!$A$3:$B$202,2,FALSE())),"")
B21: =IFERROR(IF(A21="","",VLOOKUP(A21,Clientes!$A$3:$B$202,2,FALSE())),"")
B22: =IFERROR(IF(A22="","",VLOOKUP(A22,Clientes!$A$3:$B$202,2,FALSE())),"")
B23: =IFERROR(IF(A23="","",VLOOKUP(A23,Clientes!$A$3:$B$202,2,FALSE())),"")
... B102: =IFERROR(IF(A102="","",VLOOKUP(A102,Clientes!$A$3:$B$202,2,FALSE())),"")

Sheet Infraestructura
A1: Infraestructura propia (VPS, RustDesk, Servidores)
A3: CONFIGURACIÓN DE RUSTDESK (Servidor propio)
A4: Servidor de IDs | B4: 217.15.168.43
A5: Servidor Relay | B5: 217.15.168.43
A6: Public Key | B6: VYb6stT2eONEvwN0o5S76kFTkmyXd4FLPnS706jt3UQ=
A8: VPS PRIVADO
A9: Tipo | B9: Campo | C9: Valor | D9: Detalle | E9: Notas
A10: VPS Privado | B10: panel | C10: https://217.15.168.43:33781/93d5752e | D10: Mysql: root->Gabriela@2025
A11: VPS Privado | C11: usuario: nvvr3udy | D11: May->May@2025 UZIEL ->Uziel@2025
A12: VPS Privado | C12: pass: 4f637072 | D12: ip:217.15.168.43
A13: VPS Privado | D13: user ubuntu: root, Gabriela@2025

Sheet Vista_Resumen
A1: Vista Consolidada por Cliente
A3: Selecciona ClienteID: | B3: T002
A5: DATOS DEL CLIENTE
A6: Nombre Corto | B6: =IFERROR(IF(VLOOKUP($B$3,Clientes!$A$3:$M$202,2,FALSE())="","",VLOOKUP($B$3,Clientes!$A$3:$M$202,2,FALSE())),"") -> ACTOPAN AGUA
A7: Razón Social | B7: =IFERROR(IF(VLOOKUP($B$3,Clientes!$A$3:$M$202,3,FALSE())="","",VLOOKUP($B$3,Clientes!$A$3:$M$202,3,FALSE())),"") -> Comisión de Agua y alcantarillado de Actopán, Hidalgo
A8: RFC | B8: =IFERROR(IF(VLOOKUP($B$3,Clientes!$A$3:$M$202,4,FALSE())="","",VLOOKUP($B$3,Clientes!$A$3:$M$202,4,FALSE())),"") -> CAA930101333
A9: Contacto | B9: =IFERROR(IF(VLOOKUP($B$3,Clientes!$A$3:$M$202,5,FALSE())="","",VLOOKUP($B$3,Clientes!$A$3:$M$202,5,FALSE())),"") -> Gris CAASA
A10: Teléfono | B10: =IFERROR(IF(VLOOKUP($B$3,Clientes!$A$3:$M$202,6,FALSE())="","",VLOOKUP($B$3,Clientes!$A$3:$M$202,6,FALSE())),"") -> 7721016818
A11: Correo | B11: =IFERROR(IF(VLOOKUP($B$3,Clientes!$A$3:$M$202,7,FALSE())="","",VLOOKUP($B$3,Clientes!$A$3:$M$202,7,FALSE())),"") -> comaguactopan@yahoo.com.mx
A12: Dirección | B12: =IFERROR(IF(VLOOKUP($B$3,Clientes!$A$3:$M$202,8,FALSE())="","",VLOOKUP($B$3,Clientes!$A$3:$M$202,8,FALSE())),"")
A13: Estatus | B13: =IFERROR(IF(VLOOKUP($B$3,Clientes!$A$3:$M$202,11,FALSE())="","",VLOOKUP($B$3,Clientes!$A$3:$M$202,11,FALSE())),"") -> Activo
A15: ACCESOS REMOTOS
A16: Tipo | B16: Equipo | C16: ID | D16: Password | E16: Notas
A17: =IFERROR(IF(INDEX(AccesosRemotos!C:C,SMALL(IF(AccesosRemotos!$A$3:$A$1000=$B$3,ROW(AccesosRemotos!$A$3:$A$1000)),1))="","",INDEX(AccesosRemotos!C:C,SMALL(IF(AccesosRemotos!$A$3:$A$1000=$B$3,ROW(AccesosRemotos!$A$3:$A$1000)),1))),"") -> RustDesk | B17: =IFERROR(IF(INDEX(AccesosRemotos!E:E,SMALL(IF(AccesosRemotos!$A$3:$A$1000=$B$3,ROW(AccesosRemotos!$A$3:$A$1000)),1))="","",INDEX(AccesosRemotos!E:E,SMALL(IF(AccesosRemotos!$A$3:$A$1000=$B$3,ROW(AccesosRemotos!$A$3:$A$1000)),1))),"") -> LAPTOP - CAJA MOVIL | C17: =IFERROR(IF(INDEX(AccesosRemotos!F:F,SMALL(IF(AccesosRemotos!$A$3:$A$1000=$B$3,ROW(AccesosRemotos!$A$3:$A$1000)),1))="","",INDEX(AccesosRemotos!F:F,SMALL(IF(AccesosRemotos!$A$3:$A$1000=$B$3,ROW(AccesosRemotos!$A$3:$A$1000)),1))),"") -> 54 631 371 | D17: =IFERROR(IF(INDEX(AccesosRemotos!G:G,SMALL(IF(AccesosRemotos!$A$3:$A$1000=$B$3,ROW(AccesosRemotos!$A$3:$A$1000)),1))="","",INDEX(AccesosRemotos!G:G,SMALL(IF(AccesosRemotos!$A$3:$A$1000=$B$3,ROW(AccesosRemotos!$A$3:$A$1000)),1))),"") | E17: =IFERROR(IF(INDEX(AccesosRemotos!H:H,SMALL(IF(AccesosRemotos!$A$3:$A$1000=$B$3,ROW(AccesosRemotos!$A$3:$A$1000)),1))="","",INDEX(AccesosRemotos!H:H,SMALL(IF(AccesosRemotos!$A$3:$A$1000=$B$3,ROW(AccesosRemotos!$A$3:$A$1000)),1))),"") -> MySQL: Gabriela@2018
A18: =IFERROR(IF(INDEX(AccesosRemotos!C:C,SMALL(IF(AccesosRemotos!$A$3:$A$1000=$B$3,ROW(AccesosRemotos!$A$3:$A$1000)),2))="","",INDEX(AccesosRemotos!C:C,SMALL(IF(AccesosRemotos!$A$3:$A$1000=$B$3,ROW(AccesosRemotos!$A$3:$A$1000)),2))),"") -> RustDesk | B18: =IFERROR(IF(INDEX(AccesosRemotos!E:E,SMALL(IF(AccesosRemotos!$A$3:$A$1000=$B$3,ROW(AccesosRemotos!$A$3:$A$1000)),2))="","",INDEX(AccesosRemotos!E:E,SMALL(IF(AccesosRemotos!$A$3:$A$1000=$B$3,ROW(AccesosRemotos!$A$3:$A$1000)),2))),"") -> SERVER | C18: =IFERROR(IF(INDEX(AccesosRemotos!F:F,SMALL(IF(AccesosRemotos!$A$3:$A$1000=$B$3,ROW(AccesosRemotos!$A$3:$A$1000)),2))="","",INDEX(AccesosRemotos!F:F,SMALL(IF(AccesosRemotos!$A$3:$A$1000=$B$3,ROW(AccesosRemotos!$A$3:$A$1000)),2))),"") -> 22 464 940 | D18: =IFERROR(IF(INDEX(AccesosRemotos!G:G,SMALL(IF(AccesosRemotos!$A$3:$A$1000=$B$3,ROW(AccesosRemotos!$A$3:$A$1000)),2))="","",INDEX(AccesosRemotos!G:G,SMALL(IF(AccesosRemotos!$A$3:$A$1000=$B$3,ROW(AccesosRemotos!$A$3:$A$1000)),2))),"") | E18: =IFERROR(IF(INDEX(AccesosRemotos!H:H,SMALL(IF(AccesosRemotos!$A$3:$A$1000=$B$3,ROW(AccesosRemotos!$A$3:$A$1000)),2))="","",INDEX(AccesosRemotos!H:H,SMALL(IF(AccesosRemotos!$A$3:$A$1000=$B$3,ROW(AccesosRemotos!$A$3:$A$1000)),2))),"") -> MySQL: Gabriela2018
A19: =IFERROR(IF(INDEX(AccesosRemotos!C:C,SMALL(IF(AccesosRemotos!$A$3:$A$1000=$B$3,ROW(AccesosRemotos!$A$3:$A$1000)),3))="","",INDEX(AccesosRemotos!C:C,SMALL(IF(AccesosRemotos!$A$3:$A$1000=$B$3,ROW(AccesosRemotos!$A$3:$A$1000)),3))),"") -> AnyDesk | B19: =IFERROR(IF(INDEX(AccesosRemotos!E:E,SMALL(IF(AccesosRemotos!$A$3:$A$1000=$B$3,ROW(AccesosRemotos!$A$3:$A$1000)),3))="","",INDEX(AccesosRemotos!E:E,SMALL(IF(AccesosRemotos!$A$3:$A$1000=$B$3,ROW(AccesosRemotos!$A$3:$A$1000)),3))),"") -> SERVIDOR COMUNIDADES | C19: =IFERROR(IF(INDEX(AccesosRemotos!F:F,SMALL(IF(AccesosRemotos!$A$3:$A$1000=$B$3,ROW(AccesosRemotos!$A$3:$A$1000)),3))="","",INDEX(AccesosRemotos!F:F,SMALL(IF(AccesosRemotos!$A$3:$A$1000=$B$3,ROW(AccesosRemotos!$A$3:$A$1000)),3))),"") -> 1835791957 | D19: =IFERROR(IF(INDEX(AccesosRemotos!G:G,SMALL(IF(AccesosRemotos!$A$3:$A$1000=$B$3,ROW(AccesosRemotos!$A$3:$A$1000)),3))="","",INDEX(AccesosRemotos!G:G,SMALL(IF(AccesosRemotos!$A$3:$A$1000=$B$3,ROW(AccesosRemotos!$A$3:$A$1000)),3))),"") | E19: =IFERROR(IF(INDEX(AccesosRemotos!H:H,SMALL(IF(AccesosRemotos!$A$3:$A$1000=$B$3,ROW(AccesosRemotos!$A$3:$A$1000)),3))="","",INDEX(AccesosRemotos!H:H,SMALL(IF(AccesosRemotos!$A$3:$A$1000=$B$3,ROW(AccesosRemotos!$A$3:$A$1000)),3))),"")
A20: =IFERROR(IF(INDEX(AccesosRemotos!C:C,SMALL(IF(AccesosRemotos!$A$3:$A$1000=$B$3,ROW(AccesosRemotos!$A$3:$A$1000)),4))="","",INDEX(AccesosRemotos!C:C,SMALL(IF(AccesosRemotos!$A$3:$A$1000=$B$3,ROW(AccesosRemotos!$A$3:$A$1000)),4))),"") -> RustDesk | B20: =IFERROR(IF(INDEX(AccesosRemotos!E:E,SMALL(IF(AccesosRemotos!$A$3:$A$1000=$B$3,ROW(AccesosRemotos!$A$3:$A$1000)),4))="","",INDEX(AccesosRemotos!E:E,SMALL(IF(AccesosRemotos!$A$3:$A$1000=$B$3,ROW(AccesosRemotos!$A$3:$A$1000)),4))),"") -> SERVIDOR COMUNIDADES | C20: =IFERROR(IF(INDEX(AccesosRemotos!F:F,SMALL(IF(AccesosRemotos!$A$3:$A$1000=$B$3,ROW(AccesosRemotos!$A$3:$A$1000)),4))="","",INDEX(AccesosRemotos!F:F,SMALL(IF(AccesosRemotos!$A$3:$A$1000=$B$3,ROW(AccesosRemotos!$A$3:$A$1000)),4))),"") -> 54 631 371 | D20: =IFERROR(IF(INDEX(AccesosRemotos!G:G,SMALL(IF(AccesosRemotos!$A$3:$A$1000=$B$3,ROW(AccesosRemotos!$A$3:$A$1000)),4))="","",INDEX(AccesosRemotos!G:G,SMALL(IF(AccesosRemotos!$A$3:$A$1000=$B$3,ROW(AccesosRemotos!$A$3:$A$1000)),4))),"") | E20: =IFERROR(IF(INDEX(AccesosRemotos!H:H,SMALL(IF(AccesosRemotos!$A$3:$A$1000=$B$3,ROW(AccesosRemotos!$A$3:$A$1000)),4))="","",INDEX(AccesosRemotos!H:H,SMALL(IF(AccesosRemotos!$A$3:$A$1000=$B$3,ROW(AccesosRemotos!$A$3:$A$1000)),4))),"")
A21: =IFERROR(IF(INDEX(AccesosRemotos!C:C,SMALL(IF(AccesosRemotos!$A$3:$A$1000=$B$3,ROW(AccesosRemotos!$A$3:$A$1000)),5))="","",INDEX(AccesosRemotos!C:C,SMALL(IF(AccesosRemotos!$A$3:$A$1000=$B$3,ROW(AccesosRemotos!$A$3:$A$1000)),5))),"") -> AnyDesk | B21: =IFERROR(IF(INDEX(AccesosRemotos!E:E,SMALL(IF(AccesosRemotos!$A$3:$A$1000=$B$3,ROW(AccesosRemotos!$A$3:$A$1000)),5))="","",INDEX(AccesosRemotos!E:E,SMALL(IF(AccesosRemotos!$A$3:$A$1000=$B$3,ROW(AccesosRemotos!$A$3:$A$1000)),5))),"") -> CAJA FIJA (TECOMATLAN) | C21: =IFERROR(IF(INDEX(AccesosRemotos!F:F,SMALL(IF(AccesosRemotos!$A$3:$A$1000=$B$3,ROW(AccesosRemotos!$A$3:$A$1000)),5))="","",INDEX(AccesosRemotos!F:F,SMALL(IF(AccesosRemotos!$A$3:$A$1000=$B$3,ROW(AccesosRemotos!$A$3:$A$1000)),5))),"") -> 1 616 631 904 | D21: =IFERROR(IF(INDEX(AccesosRemotos!G:G,SMALL(IF(AccesosRemotos!$A$3:$A$1000=$B$3,ROW(AccesosRemotos!$A$3:$A$1000)),5))="","",INDEX(AccesosRemotos!G:G,SMALL(IF(AccesosRemotos!$A$3:$A$1000=$B$3,ROW(AccesosRemotos!$A$3:$A$1000)),5))),"") | E21: =IFERROR(IF(INDEX(AccesosRemotos!H:H,SMALL(IF(AccesosRemotos!$A$3:$A$1000=$B$3,ROW(AccesosRemotos!$A$3:$A$1000)),5))="","",INDEX(AccesosRemotos!H:H,SMALL(IF(AccesosRemotos!$A$3:$A$1000=$B$3,ROW(AccesosRemotos!$A$3:$A$1000)),5))),"")
A22: =IFERROR(IF(INDEX(AccesosRemotos!C:C,SMALL(IF(AccesosRemotos!$A$3:$A$1000=$B$3,ROW(AccesosRemotos!$A$3:$A$1000)),6))="","",INDEX(AccesosRemotos!C:C,SMALL(IF(AccesosRemotos!$A$3:$A$1000=$B$3,ROW(AccesosRemotos!$A$3:$A$1000)),6))),"") -> RustDesk | B22: =IFERROR(IF(INDEX(AccesosRemotos!E:E,SMALL(IF(AccesosRemotos!$A$3:$A$1000=$B$3,ROW(AccesosRemotos!$A$3:$A$1000)),6))="","",INDEX(AccesosRemotos!E:E,SMALL(IF(AccesosRemotos!$A$3:$A$1000=$B$3,ROW(AccesosRemotos!$A$3:$A$1000)),6))),"") -> CAJA FIJA (TECOMATLAN) | C22: =IFERROR(IF(INDEX(AccesosRemotos!F:F,SMALL(IF(AccesosRemotos!$A$3:$A$1000=$B$3,ROW(AccesosRemotos!$A$3:$A$1000)),6))="","",INDEX(AccesosRemotos!F:F,SMALL(IF(AccesosRemotos!$A$3:$A$1000=$B$3,ROW(AccesosRemotos!$A$3:$A$1000)),6))),"") -> 22 455 870 | D22: =IFERROR(IF(INDEX(AccesosRemotos!G:G,SMALL(IF(AccesosRemotos!$A$3:$A$1000=$B$3,ROW(AccesosRemotos!$A$3:$A$1000)),6))="","",INDEX(AccesosRemotos!G:G,SMALL(IF(AccesosRemotos!$A$3:$A$1000=$B$3,ROW(AccesosRemotos!$A$3:$A$1000)),6))),"") | E22: =IFERROR(IF(INDEX(AccesosRemotos!H:H,SMALL(IF(AccesosRemotos!$A$3:$A$1000=$B$3,ROW(AccesosRemotos!$A$3:$A$1000)),6))="","",INDEX(AccesosRemotos!H:H,SMALL(IF(AccesosRemotos!$A$3:$A$1000=$B$3,ROW(AccesosRemotos!$A$3:$A$1000)),6))),"")
A23: =IFERROR(IF(INDEX(AccesosRemotos!C:C,SMALL(IF(AccesosRemotos!$A$3:$A$1000=$B$3,ROW(AccesosRemotos!$A$3:$A$1000)),7))="","",INDEX(AccesosRemotos!C:C,SMALL(IF(AccesosRemotos!$A$3:$A$1000=$B$3,ROW(AccesosRemotos!$A$3:$A$1000)),7))),"") -> AnyDesk | B23: =IFERROR(IF(INDEX(AccesosRemotos!E:E,SMALL(IF(AccesosRemotos!$A$3:$A$1000=$B$3,ROW(AccesosRemotos!$A$3:$A$1000)),7))="","",INDEX(AccesosRemotos!E:E,SMALL(IF(AccesosRemotos!$A$3:$A$1000=$B$3,ROW(AccesosRemotos!$A$3:$A$1000)),7))),"") -> CAJA FIJA (SANTIAGO) | C23: =IFERROR(IF(INDEX(AccesosRemotos!F:F,SMALL(IF(AccesosRemotos!$A$3:$A$1000=$B$3,ROW(AccesosRemotos!$A$3:$A$1000)),7))="","",INDEX(AccesosRemotos!F:F,SMALL(IF(AccesosRemotos!$A$3:$A$1000=$B$3,ROW(AccesosRemotos!$A$3:$A$1000)),7))),"") -> 1175112487 | D23: =IFERROR(IF(INDEX(AccesosRemotos!G:G,SMALL(IF(AccesosRemotos!$A$3:$A$1000=$B$3,ROW(AccesosRemotos!$A$3:$A$1000)),7))="","",INDEX(AccesosRemotos!G:G,SMALL(IF(AccesosRemotos!$A$3:$A$1000=$B$3,ROW(AccesosRemotos!$A$3:$A$1000)),7))),"") | E23: =IFERROR(IF(INDEX(AccesosRemotos!H:H,SMALL(IF(AccesosRemotos!$A$3:$A$1000=$B$3,ROW(AccesosRemotos!$A$3:$A$1000)),7))="","",INDEX(AccesosRemotos!H:H,SMALL(IF(AccesosRemotos!$A$3:$A$1000=$B$3,ROW(AccesosRemotos!$A$3:$A$1000)),7))),"")
A24: =IFERROR(IF(INDEX(AccesosRemotos!C:C,SMALL(IF(AccesosRemotos!$A$3:$A$1000=$B$3,ROW(AccesosRemotos!$A$3:$A$1000)),8))="","",INDEX(AccesosRemotos!C:C,SMALL(IF(AccesosRemotos!$A$3:$A$1000=$B$3,ROW(AccesosRemotos!$A$3:$A$1000)),8))),"") -> RustDesk | B24: =IFERROR(IF(INDEX(AccesosRemotos!E:E,SMALL(IF(AccesosRemotos!$A$3:$A$1000=$B$3,ROW(AccesosRemotos!$A$3:$A$1000)),8))="","",INDEX(AccesosRemotos!E:E,SMALL(IF(AccesosRemotos!$A$3:$A$1000=$B$3,ROW(AccesosRemotos!$A$3:$A$1000)),8))),"") -> CAJA FIJA (SANTIAGO) | C24: =IFERROR(IF(INDEX(AccesosRemotos!F:F,SMALL(IF(AccesosRemotos!$A$3:$A$1000=$B$3,ROW(AccesosRemotos!$A$3:$A$1000)),8))="","",INDEX(AccesosRemotos!F:F,SMALL(IF(AccesosRemotos!$A$3:$A$1000=$B$3,ROW(AccesosRemotos!$A$3:$A$1000)),8))),"") -> 22 471 019 | D24: =IFERROR(IF(INDEX(AccesosRemotos!G:G,SMALL(IF(AccesosRemotos!$A$3:$A$1000=$B$3,ROW(AccesosRemotos!$A$3:$A$1000)),8))="","",INDEX(AccesosRemotos!G:G,SMALL(IF(AccesosRemotos!$A$3:$A$1000=$B$3,ROW(AccesosRemotos!$A$3:$A$1000)),8))),"") | E24: =IFERROR(IF(INDEX(AccesosRemotos!H:H,SMALL(IF(AccesosRemotos!$A$3:$A$1000=$B$3,ROW(AccesosRemotos!$A$3:$A$1000)),8))="","",INDEX(AccesosRemotos!H:H,SMALL(IF(AccesosRemotos!$A$3:$A$1000=$B$3,ROW(AccesosRemotos!$A$3:$A$1000)),8))),"")
A25: =IFERROR(IF(INDEX(AccesosRemotos!C:C,SMALL(IF(AccesosRemotos!$A$3:$A$1000=$B$3,ROW(AccesosRemotos!$A$3:$A$1000)),9))="","",INDEX(AccesosRemotos!C:C,SMALL(IF(AccesosRemotos!$A$3:$A$1000=$B$3,ROW(AccesosRemotos!$A$3:$A$1000)),9))),"") -> AnyDesk | B25: =IFERROR(IF(INDEX(AccesosRemotos!E:E,SMALL(IF(AccesosRemotos!$A$3:$A$1000=$B$3,ROW(AccesosRemotos!$A$3:$A$1000)),9))="","",INDEX(AccesosRemotos!E:E,SMALL(IF(AccesosRemotos!$A$3:$A$1000=$B$3,ROW(AccesosRemotos!$A$3:$A$1000)),9))),"") -> JOSELINE | C25: =IFERROR(IF(INDEX(AccesosRemotos!F:F,SMALL(IF(AccesosRemotos!$A$3:$A$1000=$B$3,ROW(AccesosRemotos!$A$3:$A$1000)),9))="","",INDEX(AccesosRemotos!F:F,SMALL(IF(AccesosRemotos!$A$3:$A$1000=$B$3,ROW(AccesosRemotos!$A$3:$A$1000)),9))),"") -> 1 805 331 651 | D25: =IFERROR(IF(INDEX(AccesosRemotos!G:G,SMALL(IF(AccesosRemotos!$A$3:$A$1000=$B$3,ROW(AccesosRemotos!$A$3:$A$1000)),9))="","",INDEX(AccesosRemotos!G:G,SMALL(IF(AccesosRemotos!$A$3:$A$1000=$B$3,ROW(AccesosRemotos!$A$3:$A$1000)),9))),"") | E25: =IFERROR(IF(INDEX(AccesosRemotos!H:H,SMALL(IF(AccesosRemotos!$A$3:$A$1000=$B$3,ROW(AccesosRemotos!$A$3:$A$1000)),9))="","",INDEX(AccesosRemotos!H:H,SMALL(IF(AccesosRemotos!$A$3:$A$1000=$B$3,ROW(AccesosRemotos!$A$3:$A$1000)),9))),"")
A26: =IFERROR(IF(INDEX(AccesosRemotos!C:C,SMALL(IF(AccesosRemotos!$A$3:$A$1000=$B$3,ROW(AccesosRemotos!$A$3:$A$1000)),10))="","",INDEX(AccesosRemotos!C:C,SMALL(IF(AccesosRemotos!$A$3:$A$1000=$B$3,ROW(AccesosRemotos!$A$3:$A$1000)),10))),"") -> RustDesk | B26: =IFERROR(IF(INDEX(AccesosRemotos!E:E,SMALL(IF(AccesosRemotos!$A$3:$A$1000=$B$3,ROW(AccesosRemotos!$A$3:$A$1000)),10))="","",INDEX(AccesosRemotos!E:E,SMALL(IF(AccesosRemotos!$A$3:$A$1000=$B$3,ROW(AccesosRemotos!$A$3:$A$1000)),10))),"") -> JOSELINE | C26: =IFERROR(IF(INDEX(AccesosRemotos!F:F,SMALL(IF(AccesosRemotos!$A$3:$A$1000=$B$3,ROW(AccesosRemotos!$A$3:$A$1000)),10))="","",INDEX(AccesosRemotos!F:F,SMALL(IF(AccesosRemotos!$A$3:$A$1000=$B$3,ROW(AccesosRemotos!$A$3:$A$1000)),10))),"") -> 252 153 309 | D26: =IFERROR(IF(INDEX(AccesosRemotos!G:G,SMALL(IF(AccesosRemotos!$A$3:$A$1000=$B$3,ROW(AccesosRemotos!$A$3:$A$1000)),10))="","",INDEX(AccesosRemotos!G:G,SMALL(IF(AccesosRemotos!$A$3:$A$1000=$B$3,ROW(AccesosRemotos!$A$3:$A$1000)),10))),"") | E26: =IFERROR(IF(INDEX(AccesosRemotos!H:H,SMALL(IF(AccesosRemotos!$A$3:$A$1000=$B$3,ROW(AccesosRemotos!$A$3:$A$1000)),10))="","",INDEX(AccesosRemotos!H:H,SMALL(IF(AccesosRemotos!$A$3:$A$1000=$B$3,ROW(AccesosRemotos!$A$3:$A$1000)),10))),"")
A27: =IFERROR(IF(INDEX(AccesosRemotos!C:C,SMALL(IF(AccesosRemotos!$A$3:$A$1000=$B$3,ROW(AccesosRemotos!$A$3:$A$1000)),11))="","",INDEX(AccesosRemotos!C:C,SMALL(IF(AccesosRemotos!$A$3:$A$1000=$B$3,ROW(AccesosRemotos!$A$3:$A$1000)),11))),"") -> AnyDesk | B27: =IFERROR(IF(INDEX(AccesosRemotos!E:E,SMALL(IF(AccesosRemotos!$A$3:$A$1000=$B$3,ROW(AccesosRemotos!$A$3:$A$1000)),11))="","",INDEX(AccesosRemotos!E:E,SMALL(IF(AccesosRemotos!$A$3:$A$1000=$B$3,ROW(AccesosRemotos!$A$3:$A$1000)),11))),"") -> AREA COMERCIAL(NELLY) | C27: =IFERROR(IF(INDEX(AccesosRemotos!F:F,SMALL(IF(AccesosRemotos!$A$3:$A$1000=$B$3,ROW(AccesosRemotos!$A$3:$A$1000)),11))="","",INDEX(AccesosRemotos!F:F,SMALL(IF(AccesosRemotos!$A$3:$A$1000=$B$3,ROW(AccesosRemotos!$A$3:$A$1000)),11))),"") -> 1703322057 | D27: =IFERROR(IF(INDEX(AccesosRemotos!G:G,SMALL(IF(AccesosRemotos!$A$3:$A$1000=$B$3,ROW(AccesosRemotos!$A$3:$A$1000)),11))="","",INDEX(AccesosRemotos!G:G,SMALL(IF(AccesosRemotos!$A$3:$A$1000=$B$3,ROW(AccesosRemotos!$A$3:$A$1000)),11))),"") | E27: =IFERROR(IF(INDEX(AccesosRemotos!H:H,SMALL(IF(AccesosRemotos!$A$3:$A$1000=$B$3,ROW(AccesosRemotos!$A$3:$A$1000)),11))="","",INDEX(AccesosRemotos!H:H,SMALL(IF(AccesosRemotos!$A$3:$A$1000=$B$3,ROW(AccesosRemotos!$A$3:$A$1000)),11))),"")
A28: =IFERROR(IF(INDEX(AccesosRemotos!C:C,SMALL(IF(AccesosRemotos!$A$3:$A$1000=$B$3,ROW(AccesosRemotos!$A$3:$A$1000)),12))="","",INDEX(AccesosRemotos!C:C,SMALL(IF(AccesosRemotos!$A$3:$A$1000=$B$3,ROW(AccesosRemotos!$A$3:$A$1000)),12))),"") -> RustDesk | B28: =IFERROR(IF(INDEX(AccesosRemotos!E:E,SMALL(IF(AccesosRemotos!$A$3:$A$1000=$B$3,ROW(AccesosRemotos!$A$3:$A$1000)),12))="","",INDEX(AccesosRemotos!E:E,SMALL(IF(AccesosRemotos!$A$3:$A$1000=$B$3,ROW(AccesosRemotos!$A$3:$A$1000)),12))),"") -> AREA COMERCIAL(NELLY) | C28: =IFERROR(IF(INDEX(AccesosRemotos!F:F,SMALL(IF(AccesosRemotos!$A$3:$A$1000=$B$3,ROW(AccesosRemotos!$A$3:$A$1000)),12))="","",INDEX(AccesosRemotos!F:F,SMALL(IF(AccesosRemotos!$A$3:$A$1000=$B$3,ROW(AccesosRemotos!$A$3:$A$1000)),12))),"") -> 251 783 645 | D28: =IFERROR(IF(INDEX(AccesosRemotos!G:G,SMALL(IF(AccesosRemotos!$A$3:$A$1000=$B$3,ROW(AccesosRemotos!$A$3:$A$1000)),12))="","",INDEX(AccesosRemotos!G:G,SMALL(IF(AccesosRemotos!$A$3:$A$1000=$B$3,ROW(AccesosRemotos!$A$3:$A$1000)),12))),"") | E28: =IFERROR(IF(INDEX(AccesosRemotos!H:H,SMALL(IF(AccesosRemotos!$A$3:$A$1000=$B$3,ROW(AccesosRemotos!$A$3:$A$1000)),12))="","",INDEX(AccesosRemotos!H:H,SMALL(IF(AccesosRemotos!$A$3:$A$1000=$B$3,ROW(AccesosRemotos!$A$3:$A$1000)),12))),"")
A29: =IFERROR(IF(INDEX(AccesosRemotos!C:C,SMALL(IF(AccesosRemotos!$A$3:$A$1000=$B$3,ROW(AccesosRemotos!$A$3:$A$1000)),13))="","",INDEX(AccesosRemotos!C:C,SMALL(IF(AccesosRemotos!$A$3:$A$1000=$B$3,ROW(AccesosRemotos!$A$3:$A$1000)),13))),"") -> RustDesk | B29: =IFERROR(IF(INDEX(AccesosRemotos!E:E,SMALL(IF(AccesosRemotos!$A$3:$A$1000=$B$3,ROW(AccesosRemotos!$A$3:$A$1000)),13))="","",INDEX(AccesosRemotos!E:E,SMALL(IF(AccesosRemotos!$A$3:$A$1000=$B$3,ROW(AccesosRemotos!$A$3:$A$1000)),13))),"") -> DIRECTOR | C29: =IFERROR(IF(INDEX(AccesosRemotos!F:F,SMALL(IF(AccesosRemotos!$A$3:$A$1000=$B$3,ROW(AccesosRemotos!$A$3:$A$1000)),13))="","",INDEX(AccesosRemotos!F:F,SMALL(IF(AccesosRemotos!$A$3:$A$1000=$B$3,ROW(AccesosRemotos!$A$3:$A$1000)),13))),"") -> 36 246 498 | D29: =IFERROR(IF(INDEX(AccesosRemotos!G:G,SMALL(IF(AccesosRemotos!$A$3:$A$1000=$B$3,ROW(AccesosRemotos!$A$3:$A$1000)),13))="","",INDEX(AccesosRemotos!G:G,SMALL(IF(AccesosRemotos!$A$3:$A$1000=$B$3,ROW(AccesosRemotos!$A$3:$A$1000)),13))),"") | E29: =IFERROR(IF(INDEX(AccesosRemotos!H:H,SMALL(IF(AccesosRemotos!$A$3:$A$1000=$B$3,ROW(AccesosRemotos!$A$3:$A$1000)),13))="","",INDEX(AccesosRemotos!H:H,SMALL(IF(AccesosRemotos!$A$3:$A$1000=$B$3,ROW(AccesosRemotos!$A$3:$A$1000)),13))),"")
A30: =IFERROR(IF(INDEX(AccesosRemotos!C:C,SMALL(IF(AccesosRemotos!$A$3:$A$1000=$B$3,ROW(AccesosRemotos!$A$3:$A$1000)),14))="","",INDEX(AccesosRemotos!C:C,SMALL(IF(AccesosRemotos!$A$3:$A$1000=$B$3,ROW(AccesosRemotos!$A$3:$A$1000)),14))),"") -> AnyDesk | B30: =IFERROR(IF(INDEX(AccesosRemotos!E:E,SMALL(IF(AccesosRemotos!$A$3:$A$1000=$B$3,ROW(AccesosRemotos!$A$3:$A$1000)),14))="","",INDEX(AccesosRemotos!E:E,SMALL(IF(AccesosRemotos!$A$3:$A$1000=$B$3,ROW(AccesosRemotos!$A$3:$A$1000)),14))),"") -> LAPTOP - CAJA MOVIL | C30: =IFERROR(IF(INDEX(AccesosRemotos!F:F,SMALL(IF(AccesosRemotos!$A$3:$A$1000=$B$3,ROW(AccesosRemotos!$A$3:$A$1000)),14))="","",INDEX(AccesosRemotos!F:F,SMALL(IF(AccesosRemotos!$A$3:$A$1000=$B$3,ROW(AccesosRemotos!$A$3:$A$1000)),14))),"") -> 1 835 791 957 | D30: =IFERROR(IF(INDEX(AccesosRemotos!G:G,SMALL(IF(AccesosRemotos!$A$3:$A$1000=$B$3,ROW(AccesosRemotos!$A$3:$A$1000)),14))="","",INDEX(AccesosRemotos!G:G,SMALL(IF(AccesosRemotos!$A$3:$A$1000=$B$3,ROW(AccesosRemotos!$A$3:$A$1000)),14))),"") | E30: =IFERROR(IF(INDEX(AccesosRemotos!H:H,SMALL(IF(AccesosRemotos!$A$3:$A$1000=$B$3,ROW(AccesosRemotos!$A$3:$A$1000)),14))="","",INDEX(AccesosRemotos!H:H,SMALL(IF(AccesosRemotos!$A$3:$A$1000=$B$3,ROW(AccesosRemotos!$A$3:$A$1000)),14))),"") -> MySQL: Gabriela@2018
A31: =IFERROR(IF(INDEX(AccesosRemotos!C:C,SMALL(IF(AccesosRemotos!$A$3:$A$1000=$B$3,ROW(AccesosRemotos!$A$3:$A$1000)),15))="","",INDEX(AccesosRemotos!C:C,SMALL(IF(AccesosRemotos!$A$3:$A$1000=$B$3,ROW(AccesosRemotos!$A$3:$A$1000)),15))),"") -> RustDesk | B31: =IFERROR(IF(INDEX(AccesosRemotos!E:E,SMALL(IF(AccesosRemotos!$A$3:$A$1000=$B$3,ROW(AccesosRemotos!$A$3:$A$1000)),15))="","",INDEX(AccesosRemotos!E:E,SMALL(IF(AccesosRemotos!$A$3:$A$1000=$B$3,ROW(AccesosRemotos!$A$3:$A$1000)),15))),"") -> LAPTOP - CAJA MOVIL | C31: =IFERROR(IF(INDEX(AccesosRemotos!F:F,SMALL(IF(AccesosRemotos!$A$3:$A$1000=$B$3,ROW(AccesosRemotos!$A$3:$A$1000)),15))="","",INDEX(AccesosRemotos!F:F,SMALL(IF(AccesosRemotos!$A$3:$A$1000=$B$3,ROW(AccesosRemotos!$A$3:$A$1000)),15))),"") -> 54 631 371 | D31: =IFERROR(IF(INDEX(AccesosRemotos!G:G,SMALL(IF(AccesosRemotos!$A$3:$A$1000=$B$3,ROW(AccesosRemotos!$A$3:$A$1000)),15))="","",INDEX(AccesosRemotos!G:G,SMALL(IF(AccesosRemotos!$A$3:$A$1000=$B$3,ROW(AccesosRemotos!$A$3:$A$1000)),15))),"") | E31: =IFERROR(IF(INDEX(AccesosRemotos!H:H,SMALL(IF(AccesosRemotos!$A$3:$A$1000=$B$3,ROW(AccesosRemotos!$A$3:$A$1000)),15))="","",INDEX(AccesosRemotos!H:H,SMALL(IF(AccesosRemotos!$A$3:$A$1000=$B$3,ROW(AccesosRemotos!$A$3:$A$1000)),15))),"") -> MySQL: Gabriela@2018
A33: TIMBRADO (API Keys)
A34: Referencia | B34: Ambiente | C34: API Key
A35: =IFERROR(IF(INDEX(APIs_Timbrado!C:C,SMALL(IF(APIs_Timbrado!$A$3:$A$300=$B$3,ROW(APIs_Timbrado!$A$3:$A$300)),1))="","",INDEX(APIs_Timbrado!C:C,SMALL(IF(APIs_Timbrado!$A$3:$A$300=$B$3,ROW(APIs_Timbrado!$A$3:$A$300)),1))),"") | B35: =IFERROR(IF(INDEX(APIs_Timbrado!E:E,SMALL(IF(APIs_Timbrado!$A$3:$A$300=$B$3,ROW(APIs_Timbrado!$A$3:$A$300)),1))="","",INDEX(APIs_Timbrado!E:E,SMALL(IF(APIs_Timbrado!$A$3:$A$300=$B$3,ROW(APIs_Timbrado!$A$3:$A$300)),1))),"") | C35: =IFERROR(IF(INDEX(APIs_Timbrado!F:F,SMALL(IF(APIs_Timbrado!$A$3:$A$300=$B$3,ROW(APIs_Timbrado!$A$3:$A$300)),1))="","",INDEX(APIs_Timbrado!F:F,SMALL(IF(APIs_Timbrado!$A$3:$A$300=$B$3,ROW(APIs_Timbrado!$A$3:$A$300)),1))),"")
A36: =IFERROR(IF(INDEX(APIs_Timbrado!C:C,SMALL(IF(APIs_Timbrado!$A$3:$A$300=$B$3,ROW(APIs_Timbrado!$A$3:$A$300)),2))="","",INDEX(APIs_Timbrado!C:C,SMALL(IF(APIs_Timbrado!$A$3:$A$300=$B$3,ROW(APIs_Timbrado!$A$3:$A$300)),2))),"") | B36: =IFERROR(IF(INDEX(APIs_Timbrado!E:E,SMALL(IF(APIs_Timbrado!$A$3:$A$300=$B$3,ROW(APIs_Timbrado!$A$3:$A$300)),2))="","",INDEX(APIs_Timbrado!E:E,SMALL(IF(APIs_Timbrado!$A$3:$A$300=$B$3,ROW(APIs_Timbrado!$A$3:$A$300)),2))),"") | C36: =IFERROR(IF(INDEX(APIs_Timbrado!F:F,SMALL(IF(APIs_Timbrado!$A$3:$A$300=$B$3,ROW(APIs_Timbrado!$A$3:$A$300)),2))="","",INDEX(APIs_Timbrado!F:F,SMALL(IF(APIs_Timbrado!$A$3:$A$300=$B$3,ROW(APIs_Timbrado!$A$3:$A$300)),2))),"")
A37: =IFERROR(IF(INDEX(APIs_Timbrado!C:C,SMALL(IF(APIs_Timbrado!$A$3:$A$300=$B$3,ROW(APIs_Timbrado!$A$3:$A$300)),3))="","",INDEX(APIs_Timbrado!C:C,SMALL(IF(APIs_Timbrado!$A$3:$A$300=$B$3,ROW(APIs_Timbrado!$A$3:$A$300)),3))),"") | B37: =IFERROR(IF(INDEX(APIs_Timbrado!E:E,SMALL(IF(APIs_Timbrado!$A$3:$A$300=$B$3,ROW(APIs_Timbrado!$A$3:$A$300)),3))="","",INDEX(APIs_Timbrado!E:E,SMALL(IF(APIs_Timbrado!$A$3:$A$300=$B$3,ROW(APIs_Timbrado!$A$3:$A$300)),3))),"") | C37: =IFERROR(IF(INDEX(APIs_Timbrado!F:F,SMALL(IF(APIs_Timbrado!$A$3:$A$300=$B$3,ROW(APIs_Timbrado!$A$3:$A$300)),3))="","",INDEX(APIs_Timbrado!F:F,SMALL(IF(APIs_Timbrado!$A$3:$A$300=$B$3,ROW(APIs_Timbrado!$A$3:$A$300)),3))),"")
A39: FACTURA.LO
A40: Razón Social | B40: RFC | C40: API Key | D40: Correo
A41: =IFERROR(IF(INDEX(APIs_FacturaLO!C:C,SMALL(IF(APIs_FacturaLO!$A$13:$A$200=$B$3,ROW(APIs_FacturaLO!$A$13:$A$200)),1))="","",INDEX(APIs_FacturaLO!C:C,SMALL(IF(APIs_FacturaLO!$A$13:$A$200=$B$3,ROW(APIs_FacturaLO!$A$13:$A$200)),1))),"") | B41: =IFERROR(IF(INDEX(APIs_FacturaLO!D:D,SMALL(IF(APIs_FacturaLO!$A$13:$A$200=$B$3,ROW(APIs_FacturaLO!$A$13:$A$200)),1))="","",INDEX(APIs_FacturaLO!D:D,SMALL(IF(APIs_FacturaLO!$A$13:$A$200=$B$3,ROW(APIs_FacturaLO!$A$13:$A$200)),1))),"") | C41: =IFERROR(IF(INDEX(APIs_FacturaLO!E:E,SMALL(IF(APIs_FacturaLO!$A$13:$A$200=$B$3,ROW(APIs_FacturaLO!$A$13:$A$200)),1))="","",INDEX(APIs_FacturaLO!E:E,SMALL(IF(APIs_FacturaLO!$A$13:$A$200=$B$3,ROW(APIs_FacturaLO!$A$13:$A$200)),1))),"") | D41: =IFERROR(IF(INDEX(APIs_FacturaLO!H:H,SMALL(IF(APIs_FacturaLO!$A$13:$A$200=$B$3,ROW(APIs_FacturaLO!$A$13:$A$200)),1))="","",INDEX(APIs_FacturaLO!H:H,SMALL(IF(APIs_FacturaLO!$A$13:$A$200=$B$3,ROW(APIs_FacturaLO!$A$13:$A$200)),1))),"")
A42: =IFERROR(IF(INDEX(APIs_FacturaLO!C:C,SMALL(IF(APIs_FacturaLO!$A$13:$A$200=$B$3,ROW(APIs_FacturaLO!$A$13:$A$200)),2))="","",INDEX(APIs_FacturaLO!C:C,SMALL(IF(APIs_FacturaLO!$A$13:$A$200=$B$3,ROW(APIs_FacturaLO!$A$13:$A$200)),2))),"") | B42: =IFERROR(IF(INDEX(APIs_FacturaLO!D:D,SMALL(IF(APIs_FacturaLO!$A$13:$A$200=$B$3,ROW(APIs_FacturaLO!$A$13:$A$200)),2))="","",INDEX(APIs_FacturaLO!D:D,SMALL(IF(APIs_FacturaLO!$A$13:$A$200=$B$3,ROW(APIs_FacturaLO!$A$13:$A$200)),2))),"") | C42: =IFERROR(IF(INDEX(APIs_FacturaLO!E:E,SMALL(IF(APIs_FacturaLO!$A$13:$A$200=$B$3,ROW(APIs_FacturaLO!$A$13:$A$200)),2))="","",INDEX(APIs_FacturaLO!E:E,SMALL(IF(APIs_FacturaLO!$A$13:$A$200=$B$3,ROW(APIs_FacturaLO!$A$13:$A$200)),2))),"") | D42: =IFERROR(IF(INDEX(APIs_FacturaLO!H:H,SMALL(IF(APIs_FacturaLO!$A$13:$A$200=$B$3,ROW(APIs_FacturaLO!$A$13:$A$200)),2))="","",INDEX(APIs_FacturaLO!H:H,SMALL(IF(APIs_FacturaLO!$A$13:$A$200=$B$3,ROW(APIs_FacturaLO!$A$13:$A$200)),2))),"")
